Workbook

Sheet Dashboard
A1: ZN Futures Position & Performance Summary
A2: CME 10-Year Treasury Note Trade Summary Card
A4: POSITION OVERVIEW | D4: FINANCIAL PERFORMANCE
A5: Contract | B5: ='Trade Calculation'!C3 -> ZN | D5: Point Profit | E5: ='Trade Calculation'!C19 -> 0
A6: Direction | B6: ='Trade Calculation'!C11 -> Short | D6: Tick Gain | E6: ='Trade Calculation'!C22 -> 0.40625
A7: Contracts (Lots) | B7: ='Trade Calculation'!C12 -> 2 | D7: Capital Required (Margin) | E7: ='Trade Calculation'!C25 -> 812.5
A8: Entry Price | B8: ='Trade Calculation'!C20 -> 106.46875 | D8: Net Profit / (Loss) | E8: ='Trade Calculation'!C24 -> 406.25
A9: Exit Price | B9: ='Trade Calculation'!C21 -> 106.0625 | D9: Return on Margin (RoM) | E9: ='Trade Calculation'!C26 -> 4400

Sheet Trade Calculation
B2: 1. Contract Specifications
B3: Ticker Symbol | C3: ZN | E3: 10-Year U.S. Treasury Note Futures
B4: Exchange | C4: CME
B5: Contract Size (Face Value) | C5: 100000
B6: Full Point Value | C6: 1000
B7: Ticks per Full Point | C7: 32 | E7: Quote Units: Points and 32nds
B8: Minimum Tick Size | C8: 0.015625
B9: Tick Value (1/64th point) | C9: =C6/(C7*2) -> 15.625
B10: 2. Trade Inputs
B11: Position Type | C11: Short
B12: Number of Contracts (Lots) | C12: 2 | E12: Position size
C14: Points | D14: Fraction
B15: Entry Price | C15: 106 | D15: 15
B16: Exit Price | C16: 106 | D16: 2
B17: Initial Margin per Contract | C17: 2200 | E17: CME / Broker required capital
B18: Maintenance Margin per Contract | C18: 1800 | E18: Minimum equity threshold
B19: 3. Analysis
B20: Entry Price (Points) | C20: =C15+(D15/$C$7) -> 106.46875 | E20: Price quoted in decimal points
B21: Exit Price (Points) | C21: =C16+(D16/$C$7) -> 106.0625 | E21: Closing price
B22: Price Difference (Points) | C22: =IF(C11="Short", C20-C21, C21-C20) -> 0.40625 | E22: Positive = Profit
B23: Price Difference in Ticks (32nds) | C23: =C22*C7 -> 13 | E23: 1 point = 32 ticks
B24: Gross P&L per Contract | C24: =C22*C6 -> 406.25 | E24: Point Change x $1,000
B25: Total Gross Profit / (Loss) | C25: =C24*C12 -> 812.5 | E25: P&L x Number of Lots
B26: Capital Required (Initial Margin) | C26: =C12*C17 -> 4400 | E26: Total Margin Posted
B27: Return on Margin (RoM) | C27: =C25/C26 -> 0.18465909 | E27: Profit / Capital Required
B28: 4. Scenario
B29: Exit Price (Points) | C29: Price Change (Pts) | D29: Ticks (32nds) | E29: Net P&L ($) | F29: Return on Margin (%)
B30: =B31+($C$48/$C$7) -> 107.0625 | C30: =$C$20-B30 -> -0.59375 | D30: =C30*$C$7 -> -19 | E30: =C30*$C$6*$C$12 -> -1187.5 | F30: =E30/$C$26 -> -0.26988636
B31: =B32+($C$48/$C$7) -> 106.9375 | C31: =$C$20-B31 -> -0.46875 | D31: =C31*$C$7 -> -15 | E31: =C31*$C$6*$C$12 -> -937.5 | F31: =E31/$C$26 -> -0.21306818
B32: =B33+($C$48/$C$7) -> 106.8125 | C32: =$C$20-B32 -> -0.34375 | D32: =C32*$C$7 -> -11 | E32: =C32*$C$6*$C$12 -> -687.5 | F32: =E32/$C$26 -> -0.15625
B33: =B34+($C$48/$C$7) -> 106.6875 | C33: =$C$20-B33 -> -0.21875 | D33: =C33*$C$7 -> -7 | E33: =C33*$C$6*$C$12 -> -437.5 | F33: =E33/$C$26 -> -0.099431818
B34: =B35+($C$48/$C$7) -> 106.5625 | C34: =$C$20-B34 -> -0.09375 | D34: =C34*$C$7 -> -3 | E34: =C34*$C$6*$C$12 -> -187.5 | F34: =E34/$C$26 -> -0.042613636
B35: =B36+($C$48/$C$7) -> 106.4375 | C35: =$C$20-B35 -> 0.03125 | D35: =C35*$C$7 -> 1 | E35: =C35*$C$6*$C$12 -> 62.5 | F35: =E35/$C$26 -> 0.014204545
B36: =B37+($C$48/$C$7) -> 106.3125 | C36: =$C$20-B36 -> 0.15625 | D36: =C36*$C$7 -> 5 | E36: =C36*$C$6*$C$12 -> 312.5 | F36: =E36/$C$26 -> 0.071022727
B37: =B38+($C$48/$C$7) -> 106.1875 | C37: =$C$20-B37 -> 0.28125 | D37: =C37*$C$7 -> 9 | E37: =C37*$C$6*$C$12 -> 562.5 | F37: =E37/$C$26 -> 0.12784091
B38: =C21 -> 106.0625 | C38: =$C$20-B38 -> 0.40625 | D38: =C38*$C$7 -> 13 | E38: =C38*$C$6*$C$12 -> 812.5 | F38: =E38/$C$26 -> 0.18465909
B39: =B38-($C$48/$C$7) -> 105.9375 | C39: =$C$20-B39 -> 0.53125 | D39: =C39*$C$7 -> 17 | E39: =C39*$C$6*$C$12 -> 1062.5 | F39: =E39/$C$26 -> 0.24147727
B40: =B39-($C$48/$C$7) -> 105.8125 | C40: =$C$20-B40 -> 0.65625 | D40: =C40*$C$7 -> 21 | E40: =C40*$C$6*$C$12 -> 1312.5 | F40: =E40/$C$26 -> 0.29829545
B41: =B40-($C$48/$C$7) -> 105.6875 | C41: =$C$20-B41 -> 0.78125 | D41: =C41*$C$7 -> 25 | E41: =C41*$C$6*$C$12 -> 1562.5 | F41: =E41/$C$26 -> 0.35511364
B42: =B41-($C$48/$C$7) -> 105.5625 | C42: =$C$20-B42 -> 0.90625 | D42: =C42*$C$7 -> 29 | E42: =C42*$C$6*$C$12 -> 1812.5 | F42: =E42/$C$26 -> 0.41193182
...

Sheet Fair Value & Spot
